wandb: Currently logged in as: crazyboy9103. Use `wandb login --relogin` to force relogin
wandb: WARNING Tried to auto resume run with id 20221029_143257 but id 20221029_144856_442 is set.
Exception in thread StatsThr:
Traceback (most recent call last):
  File "/home/kwangyeongill/anaconda/envs/FedSSL/lib/python3.9/threading.py", line 973, in _bootstrap_inner
    self.run()
  File "/home/kwangyeongill/anaconda/envs/FedSSL/lib/python3.9/threading.py", line 910, in run
    self._target(*self._args, **self._kwargs)
  File "/home/kwangyeongill/anaconda/envs/FedSSL/lib/python3.9/site-packages/wandb/sdk/internal/stats.py", line 138, in _thread_body
    stats = self.stats()
  File "/home/kwangyeongill/anaconda/envs/FedSSL/lib/python3.9/site-packages/wandb/sdk/internal/stats.py", line 184, in stats
    handle = pynvml.nvmlDeviceGetHandleByIndex(i)
  File "/home/kwangyeongill/anaconda/envs/FedSSL/lib/python3.9/site-packages/wandb/vendor/pynvml/pynvml.py", line 819, in nvmlDeviceGetHandleByIndex
    _nvmlCheckReturn(ret)
  File "/home/kwangyeongill/anaconda/envs/FedSSL/lib/python3.9/site-packages/wandb/vendor/pynvml/pynvml.py", line 310, in _nvmlCheckReturn
    raise NVMLError(ret)
wandb.vendor.pynvml.pynvml.NVMLError_Unknown: Unknown Error
wandb: wandb version 0.13.4 is available!  To upgrade, please run:
wandb:  $ pip install wandb --upgrade
wandb: Tracking run with wandb version 0.13.1
wandb: Run data is saved locally in /home/kwangyeongill/FedSSL_new/wandb/run-20221029_144859-20221029_144856_442
wandb: Run `wandb offline` to turn off syncing.
wandb: Syncing run simsiam_FedSSL_iid_ema_0.1
wandb: ‚≠êÔ∏è View project at https://wandb.ai/crazyboy9103/Fed
wandb: üöÄ View run at https://wandb.ai/crazyboy9103/Fed/runs/20221029_144856_442
Files already downloaded and verified
Files already downloaded and verified
